<robot name="balance_car">

    <material name="white">
        <color rgba="1 1 1 1"/>
    </material>

    <material name="blue">
        <color rgba="0.5 0.5 1 1"/>
    </material>

    <link name="base">
        <visual>
            <geometry>
                <box size="0.2 0.6 0.8"/>
            </geometry>
            <material name="white"/>
        </visual>
        <collision>
            <geometry>
                <box size="0.2 0.6 0.8"/>
            </geometry>
        </collision>
        <inertial>
           <mass value="3"/>
           <inertia ixx="1e-3" ixy="0.0" ixz="0.0" iyy="1e-3" iyz="0.0" izz="1e-3"/>
        </inertial>
    </link>

    <link name="left_wheel">
        <contact>
            <lateral_friction value="1"/>
        </contact>
        <visual>
           <geometry>
                <cylinder length="0.1" radius="0.2"/>
           </geometry>
           <origin rpy="1.57075 0 0" xyz="0 0 0"/>
           <material name="blue"/>
        </visual>
        <collision>
            <geometry>
                <cylinder length="0.1" radius="0.2"/>
           </geometry>
           <origin rpy="1.57075 0 0" xyz="0 0 0"/>
        </collision>
        <inertial>
           <mass value="0.3"/>
           <inertia ixx="1e-3" ixy="0.0" ixz="0.0" iyy="1e-3" iyz="0.0" izz="1e-3"/>
        </inertial>
    </link>

    <link name="right_wheel">
        <contact>
            <lateral_friction value="1"/>
        </contact>
        <visual>
           <geometry>
                <cylinder length="0.1" radius="0.2"/>
           </geometry>
           <origin rpy="1.57075 0 0" xyz="0 0 0"/>
           <material name="blue"/>
        </visual>
        <collision>
            <geometry>
                <cylinder length="0.1" radius="0.2"/>
           </geometry>
           <origin rpy="1.57075 0 0" xyz="0 0 0"/>
        </collision>
        <inertial>
           <mass value="0.3"/>
           <inertia ixx="1e-3" ixy="0.0" ixz="0.0" iyy="1e-3" iyz="0.0" izz="1e-3"/>
        </inertial>
    </link>

    <joint name="base_to_left" type="continuous">
        <axis xyz="0 -1 0"/>
        <parent link="base"/>
        <child link="left_wheel"/>
        <origin rpy="0 0 0" xyz="0 -0.35 -0.3"/>
    </joint>

    <joint name="base_to_right" type="continuous">
        <axis xyz="0 1 0"/>
        <parent link="base"/>
        <child link="right_wheel"/>
        <origin rpy="0 0 0" xyz="0 0.35 -0.3"/>
    </joint>

</robot>
